<?xml version="1.0"?>
<robot xmlns:sensor="http://playerstage.sourceforge.net/gazebo/xmlschema/#sensor"
	   xmlns:controller="http://playerstage.sourceforge.net/gazebo/
	   xmlschema/#controller"
	   xmlns:interface="http://playerstage.sourceforge.net/gazebo/xmlschema/#interface"
	   xmlns:xacro="http://ros.org/wiki/xacro"
	   >
  
	<include filename="$(find p2os_urdf)/defs/pioneer3dx_wheel.xacro"/>

	<!-- Chassis description -->
	<link name="$(arg prefix)/base_link">
		<!-- CHECK THESE VALUES. THEY MAY BE COMPLETELY WRONG. -->
		<inertial>
			<mass value="40.0"/>
			<origin xyz="-0.045 0 0.148"/>
			<inertia ixx="0.3338" ixy="0.0" ixz="0.0"
				 iyy="0.4783" iyz="0.0"
				 izz="0.3338"/>
		</inertial>
		<!-- The base visual is fine. Just the inertial is questionable.-->
		<visual name="pioneer_geom">
			<origin xyz="-0.045 0 0.148" rpy="0 0 0"/>
			<geometry name="pioneer_geom">
				<mesh filename="package://p2os_urdf/meshes/p3dx_meshes/chassis.stl"/>
			</geometry>
			<material name="ChassisRed">
				<color rgba="0.851 0.0 0.0 1.0"/>
			</material>
		</visual>
		<collision>
			<origin xyz="-0.045 0 0.148" rpy="0 0 0"/>
				<geometry>
					<mesh filename="package://p2os_urdf/meshes/p3at_meshes/chassis.stl"/>
				</geometry>
		</collision>
	</link>
	<gazebo reference="base_link">
		<material value="Gazebo/Red"/>
	</gazebo>

	<link name="$(arg prefix)/top_plate">
		<inertial>
			<mass value="0.01"/>	
			<origin xyz="0 0 0"/>
			<inertia ixx="1" ixy="0" ixz="0"
				 iyy="1" iyz="0"
 				izz="1"/>
		</inertial>
		<visual name="pioneer_geom">
			<origin xyz="0 0 0" rpy="0 0 0"/>
			<geometry name="pioneer_geom">
				<mesh filename="package://p2os_urdf/meshes/p3dx_meshes/top.stl"/>
			</geometry>
			<material name="TopBlack">
					<color rgba="0.038 0.038 0.038 1.0"/>
			</material>
		</visual>
	</link>
	<gazebo reference="$(arg prefix)/top_plate">
		<material value="Gazebo/Black"/>
	</gazebo>

	<joint name="base_top_joint" type="fixed">
		<origin xyz="-0.045 0 0.24" rpy="0 0 0"/>
		<parent link="$(arg prefix)/base_link"/>
		<child link="$(arg prefix)/top_plate"/>
	</joint>

	<!-- Swivel -->
	<joint name="base_swivel_joint" type="continuous">
		<origin xyz="-0.185 0 0.055" rpy="0 0 0"/>
    <axis xyz="0 0 1"/>
    <anchor xyz="0 0 0"/>
    <limit effort="100" k_velocity="0" velocity="100"/>
    <joint_properties damping="0.0" friction="0.0"/>
		<parent link="$(arg prefix)/base_link"/>
		<child link="swivel"/>
	</joint>
	<link name="swivel">
		<inertial>
			<mass value="0.1"/>	
			<origin xyz="0 0 0"/>
			<inertia ixx="0.01" ixy="0" ixz="0"
				 iyy="0.01" iyz="0" izz="0.01"/>
  	 	</inertial>
	<visual name="pioneer_geom">
		<origin xyz="0 0 0" rpy="0 0 0"/>
		<geometry name="pioneer_geom">
			<mesh filename="package://p2os_urdf/meshes/p3dx_meshes/swivel.stl"/>
		</geometry>
		<material name="swivel">
			<color rgba="0.5 0.5 0.5 1"/>
		</material>
	</visual>
	<collision>
		<origin xyz="0 0 0" rpy="0 0 0"/>
		<geometry>
			<box size="0 0 0"/>
		</geometry>
	</collision>
	</link>
	<gazebo reference="swivel">
		<material value="Gazebo/Grey"/>
	</gazebo>

<!-- Center Wheel + Hubcap -->
	<link name="center_hubcap">
		<inertial>
			<mass value="0.01"/>	
			<origin xyz="0 0 0"/>
			<inertia ixx="0.012411765597" ixy="-0.000711733678" ixz="0.00050272983"
				 iyy="0.015218160428" iyz="-0.000004273467" izz="0.011763977943"/>
  	 	</inertial>
	<visual name="pioneer_geom">
		<origin xyz="0 0 0" rpy="0 0 0"/>
		<geometry name="pioneer_geom">
			<mesh filename="package://p2os_urdf/meshes/p3dx_meshes/center_hubcap.stl"/>
		</geometry>
		<material name="swivel">
			<color rgba="0.5 0.5 0.5 1"/>
		</material>
	</visual>
	<collision>
		<origin xyz="0 0 0" rpy="0 0 0"/>
		<geometry>
			<box size="0.05 0.05 0.05"/>
		</geometry>
	</collision>
	</link>
	<gazebo reference="center_hubcap">
		<material value="Gazebo/Grey"/>
	</gazebo>

	<joint name="swivel_hubcap_joint" type="continuous">
		<origin xyz="-0.026 0 -0.02" rpy="0 0 0"/>
		<axis xyz="0 1 0"/>
		<anchor xyz="0 0 0"/>
    <limit effort="100" velocity="100" k_velocity="0" />
    <joint_properties damping="0.0" friction="0.0" />
	  <parent link="swivel"/>
		<child link="center_wheel"/>
	</joint>

	<link name="center_wheel">
		<inertial>
			<mass value="0.1"/>	
			<origin xyz="0 0 0"/>
			<inertia ixx="0.012411765597" ixy="-0.000711733678" ixz="0.00050272983"
				 iyy="0.015218160428" iyz="-0.000004273467" izz="0.011763977943"/>
	 	</inertial>
	  <visual name="pioneer_geom">
		  <origin xyz="0 0 0" rpy="0 0 0"/>
		  <geometry name="pioneer_geom">
			  <mesh filename="package://p2os_urdf/meshes/p3dx_meshes/center_wheel.stl"/>
		  </geometry>
		  <material name="WheelBlack">
			  <color rgba="0.117 0.117 0.117 1"/>
		  </material>
	  </visual>
	<collision>
		<origin xyz="0 0 0" rpy="${-3.1415927/2.0} 0 0"/>
		<geometry>
			<!--<mesh filename="package://p2os_urdf/meshes/p3dx_meshes/center_wheel.stl"/>-->
			<cylinder radius="0.045" length="0.01"/>
		</geometry>
	</collision>
	</link>
	<gazebo reference="left_hub">
		<material value="Gazebo/Yellow"/>
	</gazebo>

	<joint name="center_wheel_joint" type="fixed">
		<origin xyz="0 0 0" rpy="0 0 0"/>
		<parent link="center_wheel"/>
		<child link="center_hubcap"/>
	</joint>

	<link name="left_hub">
		<visual>
			<origin xyz="0 0 0" rpy="0 0 0"/>
			<geometry>
				<mesh filename="package://p2os_urdf/meshes/p3dx_meshes/left_hubcap.stl"/>
			</geometry>
			<material name="HubcapYellow">
				<color rgba="1.0 0.811 0.151 1.0"/>
			</material>
		</visual>
		<collision>
			<origin xyz="0 0 0" rpy="${-3.1415927/2.0} 0 0"/>
			<geometry>
				<!--<mesh filename="package://p2os_urdf/meshes/p3dx_meshes/center_wheel.stl"/>-->
				<cylinder radius="0.09" length="0.01"/>
			</geometry>
		</collision>
	</link>
  <!-- problem -->
	<joint name="left_hub_joint" type="continuous">
		<origin xyz="0 0.15 0.08" rpy="0 0 0"/>
		<parent link="$(arg prefix)/base_link"/>
		<child link="left_hub"/>
		<axis xyz="0 1 0"/>
	</joint>

	<link name="left_wheel">
    <inertial>
      <mass value="0.5"/>
      <origin xyz="0 0 0"/>
      <inertia ixx="0.012411765597" ixy="0" ixz="0" 
              iyy="0.015218160428" iyz="0" izz="0.011763977943"/>
    </inertial>
		<visual>
			<origin xyz="0 0 0" rpy="0 0 0"/>
			<geometry>
				<mesh filename="package://p2os_urdf/meshes/p3dx_meshes/left_wheel.stl"/>
			</geometry>
			<material name="WheelBlack">
				<color rgba="0.117 0.117 0.117 1"/>
			</material>
		</visual>
    <collision>
      <origin rpy="-1.57079635 0 0" xyz="0 0 0"/>
      <geometry>
        <!--<mesh filename="package://p2os_urdf/meshes/p3dx_meshes/${suffix}_wheel.stl"/>-->
        <cylinder length="0.01" radius="0.09"/>
      </geometry>
    </collision>
	</link>

	<joint name="left_wheel_joint" type="fixed">
		<origin xyz="0 0 0" rpy="0 0 0"/>
		<parent link="left_hub"/>
		<child link="left_wheel"/>
	</joint>
	
	<gazebo reference="left_wheel">
		<material value="Gazebo/Black"/>
	</gazebo>

	<link name="right_hub">
		<visual>
			<origin xyz="0 0 0" rpy="0 0 0"/>
			<geometry>
				<mesh filename="package://p2os_urdf/meshes/p3dx_meshes/right_hubcap.stl"/>
			</geometry>
			<material name="HubcapYellow">
				<color rgba="1.0 0.811 0.151 1.0"/>
			</material>
		</visual>
		<collision>
		<origin xyz="0 0 0" rpy="${-3.1415927/2.0} 0 0"/>
		<geometry>
			<!--<mesh filename="package://p2os_urdf/meshes/p3dx_meshes/center_wheel.stl"/>-->
			<cylinder radius="0.09" length="0.01"/>
		</geometry>
	</collision>
	</link>
	<gazebo reference="right_hub">
		<material value="Gazebo/Yellow"/>
	</gazebo>
  <!-- problem -->
	<joint name="right_hub_joint" type="continuous">
		<origin xyz="0 -0.15 0.08" rpy="0 0 0"/>
		<parent link="$(arg prefix)/base_link"/>
		<child link="right_hub"/>
		<axis xyz="0 1 0"/>
	</joint>

	<link name="right_wheel">
    <inertial>
      <mass value="0.5"/>
      <origin xyz="0 0 0"/>
      <inertia ixx="0.012411765597" ixy="0" ixz="0"
               iyy="0.015218160428" iyz="0" izz="0.011763977943"/>
    </inertial>
		<visual>
			<origin xyz="0 0 0" rpy="0 0 0"/>
			<geometry>
				<mesh filename="package://p2os_urdf/meshes/p3dx_meshes/right_wheel.stl"/>
			</geometry>
			<material name="WheelBlack">
				<color rgba="0.117 0.117 0.117 1"/>
			</material>
		</visual>
    <collision>
      <origin rpy="-1.57079635 0 0" xyz="0 0 0"/>
      <geometry>
        <!--<mesh filename="package://p2os_urdf/meshes/p3dx_meshes/${suffix}_wheel.stl"/>-->
        <cylinder length="0.01" radius="0.09"/>
      </geometry>
    </collision>
	</link>

	<joint name="right_wheel_joint" type="fixed">
		<origin xyz="0 0 0" rpy="0 0 0"/>
		<parent link="right_hub"/>
		<child link="right_wheel"/>
	</joint>
	<gazebo reference="right_wheel">
		<material value="Gazebo/Black"/>
	</gazebo>

  <!-- hokuyo part -->
  <link name="$(arg prefix)/hokuyo_link">
    <inertial>
      <mass value="0.00001"/>
      <origin xyz="0 0 0"/>
      <inertia ixx="0.000001" ixy="0" ixz="0" iyy="0.000001" iyz="0" izz="0.000001"/>
    </inertial>
    <visual name="hokuyo_vis">
      <origin rpy="0 0 0" xyz="0 0 0"/>
      <geometry name="hokuyo_geom">
        <mesh filename="model://hokuyo/meshes/hokuyo.dae"/>
      </geometry>
    </visual>
    <collision>
      <origin rpy="0 0 0" xyz="0 0 0"/>
      <geometry>
        <box size="0.1 0.1 0.1"/>
      </geometry>
    </collision>
  </link>
  <joint name="hokuyo_joint" type="fixed">
    <origin rpy="0 0 0" xyz="0 0 0.28"/>
    <parent link="$(arg prefix)/base_link"/>
    <child link="$(arg prefix)/hokuyo_link"/>
  </joint>
  
  <!-- camera -->
  <!--
  <joint name="$(arg prefix)/camera_joint" type="fixed">
    <axis xyz="0 1 0" />
    <origin xyz="0.15 0.0 0.15" rpy="0 0 0"/>
    <parent link="$(arg prefix)/base_link"/>
    <child link="$(arg prefix)/camera_link"/>
  </joint>
  <link name="$(arg prefix)/camera_link">
    <collision>
      <origin xyz="0 0 0" rpy="0 0 0"/>
      <geometry>
    <box size="0.05 0.05 0.05"/>
      </geometry>
    </collision>
    
    <visual>
      <origin xyz="0 0 0" rpy="0 0 0"/>
      <geometry>
    <box size="0.05 0.05 0.05"/>
      </geometry>
      <material name="red"/>
    </visual>
    
    <inertial>
      <mass value="1e-5" />
      <origin xyz="0 0 0" rpy="0 0 0"/>
      <inertia ixx="1e-6" ixy="0" ixz="0" iyy="1e-6" iyz="0" izz="1e-6" />
    </inertial>
  </link>
  
  <gazebo reference="$(arg prefix)/camera_link">
    <sensor type="camera" name="$(arg prefix)/camera">
      <update_rate>20.0</update_rate>
      <camera name="$(arg prefix)/head">
        <horizontal_fov>1.3962634</horizontal_fov>
        <image>
          <width>120</width>
          <height>80</height>
          <format>R8G8B8</format>
        </image>
        <clip>
          <near>0.02</near>
          <far>300</far>
        </clip>
        <noise>
          <type>gaussian</type>
          <mean>0.0</mean>
          <stddev>0.007</stddev>
        </noise>
      </camera>
      <plugin name="camera_controller" filename="libgazebo_ros_camera.so">
        <alwaysOn>true</alwaysOn>
        <updateRate>0.0</updateRate>
        <cameraName>camera</cameraName>
        <imageTopicName>$(arg prefix)/image_raw</imageTopicName>
        <cameraInfoTopicName>$(arg prefix)/camera_info</cameraInfoTopicName>
        <frameName>$(arg prefix)/camera_link</frameName>
        <hackBaseline>0.07</hackBaseline>
        <distortionK1>0.0</distortionK1>
        <distortionK2>0.0</distortionK2>
        <distortionK3>0.0</distortionK3>
        <distortionT1>0.0</distortionT1>
        <distortionT2>0.0</distortionT2>
      </plugin>
    </sensor>
  </gazebo>
  -->

  <gazebo reference="$(arg prefix)/hokuyo_link">
    <sensor type="gpu_ray" name="head_hokuyo_sensor">
      <pose>0 0 0 0 0 0</pose>
      <visualize>false</visualize>
      <update_rate>20</update_rate>
      <ray>
        <scan>
          <horizontal>
            <samples>300</samples>
            <resolution>1</resolution>
            <min_angle>-1.5</min_angle>
            <max_angle>1.5</max_angle>
          </horizontal>
        </scan>
        <range>
          <min>0.10</min>
          <max>10.0</max>
          <resolution>0.01</resolution>
        </range>
        <noise>
          <type>gaussian</type>
          <!-- Noise parameters based on published spec for Hokuyo laser
               achieving "+-30mm" accuracy at range < 10m.  A mean of 0.0m and
               stddev of 0.01m will put 99.7% of samples within 0.03m of the true
               reading. -->
          <mean>0.0</mean>
          <stddev>0.01</stddev>
        </noise>
      </ray>
      <plugin name="gazebo_ros_head_hokuyo_controller" filename="libgazebo_ros_gpu_laser.so">
        <topicName>$(arg prefix)/laser/scan</topicName>
        <frameName>hokuyo_link</frameName>
      </plugin>
    </sensor>
  </gazebo>
	
	<gazebo>
	  <plugin name="differential_drive_controller"
            filename="libgazebo_ros_diff_drive.so">
	    <updateRate>100.0</updateRate>
	    <leftJoint>right_hub_joint</leftJoint>
	    <rightJoint>left_hub_joint</rightJoint>
	    <wheelSeparation>0.3</wheelSeparation>
	    <wheelDiameter>0.18</wheelDiameter>
	    <robotBaseFrame>$(arg prefix)/base_link</robotBaseFrame>
	    <torque>20</torque>
      <wheelTorque>5</wheelTorque>
	    <commandTopic>cmd_vel</commandTopic>
	    <odometryTopic>$(arg prefix)/odom</odometryTopic>
	    <odometryFrame>$(arg prefix)/odom</odometryFrame>
      <publishTf>1</publishTf>
      <odometrySource>1</odometrySource>
      <publishWheelJointState>false</publishWheelJointState>
      <publishWheelTF>false</publishWheelTF>
      <wheelAcceleration>0</wheelAcceleration>
      <rosDebugLevel>na</rosDebugLevel>
	  </plugin>
	</gazebo>
  <xacro:macro name="p3dx_gazebo_ext">
	</xacro:macro>
</robot>
